<?xml version="1.0" ?>
<!-- =================================================================================== -->
<!-- |    This document was autogenerated by xacro from .\urdf\Car_2_2023.10.04.xacro  | -->
<!-- |    EDITING THIS FILE BY HAND IS NOT RECOMMENDED                                 | -->
<!-- =================================================================================== -->
<robot xmlns:xacro="http://www.ros.org/wiki/xacro" name="Car_2_2023.10.04">
  <material name="silver">
    <color rgba="0.700 0.700 0.700 1.000"/>
  </material>
  <transmission name="Revolute 1_tran">
    <type>transmission_interface/SimpleTransmission</type>
    <joint name="Revolute 1">
      <hardwareInterface>hardware_interface/EffortJointInterface</hardwareInterface>
    </joint>
    <actuator name="Revolute 1_actr">
      <hardwareInterface>hardware_interface/EffortJointInterface</hardwareInterface>
      <mechanicalReduction>1</mechanicalReduction>
    </actuator>
  </transmission>
  <transmission name="Revolute 2_tran">
    <type>transmission_interface/SimpleTransmission</type>
    <joint name="Revolute 2">
      <hardwareInterface>hardware_interface/EffortJointInterface</hardwareInterface>
    </joint>
    <actuator name="Revolute 2_actr">
      <hardwareInterface>hardware_interface/EffortJointInterface</hardwareInterface>
      <mechanicalReduction>1</mechanicalReduction>
    </actuator>
  </transmission>
  <transmission name="Revolute 3_tran">
    <type>transmission_interface/SimpleTransmission</type>
    <joint name="Revolute 3">
      <hardwareInterface>hardware_interface/EffortJointInterface</hardwareInterface>
    </joint>
    <actuator name="Revolute 3_actr">
      <hardwareInterface>hardware_interface/EffortJointInterface</hardwareInterface>
      <mechanicalReduction>1</mechanicalReduction>
    </actuator>
  </transmission>
  <gazebo>
    <plugin name="control" filename="libgazebo_ros_control.so"/>
  </gazebo>
  <gazebo reference="base_link">
    <material>Gazebo/Silver</material>
    <mu1>0.2</mu1>
    <mu2>0.2</mu2>
    <selfCollide>true</selfCollide>
    <gravity>true</gravity>
  </gazebo>
  <gazebo reference="Right_Back_Wheel_1">
    <material>Gazebo/Silver</material>
    <mu1>0.2</mu1>
    <mu2>0.2</mu2>
    <selfCollide>true</selfCollide>
  </gazebo>
  <gazebo reference="Left_Back_Wheel_1">
    <material>Gazebo/Silver</material>
    <mu1>0.2</mu1>
    <mu2>0.2</mu2>
    <selfCollide>true</selfCollide>
  </gazebo>
  <gazebo reference="Lidar_1">
    <material>Gazebo/Silver</material>
    <mu1>0.2</mu1>
    <mu2>0.2</mu2>
    <selfCollide>true</selfCollide>
  </gazebo>
  <link name="base_link">
    <inertial>
      <origin xyz="-0.05863109688907081 -0.06641556545599622 0.05668525323671206" rpy="0 0 0"/>
      <mass value="67.11125811900729"/>
      <inertia ixx="0.355034" iyy="0.7422" izz="0.966318" ixy="-0.0" iyz="0.0" ixz="-0.001566"/>
    </inertial>
    <visual>
      <origin xyz="0 0 0" rpy="0 0 0"/>
      <geometry>
        <mesh filename="package://Car_2_2023.10.04_description/meshes/base_link.stl" scale="0.001 0.001 0.001"/>
      </geometry>
      <material name="silver"/>
    </visual>
    <collision>
      <origin xyz="0 0 0" rpy="0 0 0"/>
      <geometry>
        <mesh filename="package://Car_2_2023.10.04_description/meshes/base_link.stl" scale="0.001 0.001 0.001"/>
      </geometry>
    </collision>
  </link>
  <link name="Right_Back_Wheel_1">
    <inertial>
      <origin xyz="1.2512502856054653e-07 -0.014999565455996011 -2.5072615004659293e-07" rpy="0 0 0"/>
      <mass value="1.3050867033395783"/>
      <inertia ixx="0.000673" iyy="0.001151" izz="0.000673" ixy="-0.0" iyz="0.0" ixz="0.0"/>
    </inertial>
    <visual>
      <origin xyz="0.21406 0.192916 -0.023225" rpy="0 0 0"/>
      <geometry>
        <mesh filename="package://Car_2_2023.10.04_description/meshes/Right_Back_Wheel_1.stl" scale="0.001 0.001 0.001"/>
      </geometry>
      <material name="silver"/>
    </visual>
    <collision>
      <origin xyz="0.21406 0.192916 -0.023225" rpy="0 0 0"/>
      <geometry>
        <mesh filename="package://Car_2_2023.10.04_description/meshes/Right_Back_Wheel_1.stl" scale="0.001 0.001 0.001"/>
      </geometry>
    </collision>
  </link>
  <link name="Left_Back_Wheel_1">
    <inertial>
      <origin xyz="1.2512502872707998e-07 0.01500043454400378 -2.5072615003965404e-07" rpy="0 0 0"/>
      <mass value="1.3050867033395783"/>
      <inertia ixx="0.000673" iyy="0.001151" izz="0.000673" ixy="0.0" iyz="0.0" ixz="0.0"/>
    </inertial>
    <visual>
      <origin xyz="0.21406 -0.060084 -0.023225" rpy="0 0 0"/>
      <geometry>
        <mesh filename="package://Car_2_2023.10.04_description/meshes/Left_Back_Wheel_1.stl" scale="0.001 0.001 0.001"/>
      </geometry>
      <material name="silver"/>
    </visual>
    <collision>
      <origin xyz="0.21406 -0.060084 -0.023225" rpy="0 0 0"/>
      <geometry>
        <mesh filename="package://Car_2_2023.10.04_description/meshes/Left_Back_Wheel_1.stl" scale="0.001 0.001 0.001"/>
      </geometry>
    </collision>
  </link>
  <link name="Lidar_1">
    <inertial>
      <origin xyz="1.2512502872014108e-07 4.3454400386333525e-07 0.009999749273849973" rpy="0 0 0"/>
      <mass value="0.6392261404112222"/>
      <inertia ixx="0.000228" iyy="0.000228" izz="0.000414" ixy="0.0" iyz="-0.0" ixz="-0.0"/>
    </inertial>
    <visual>
      <origin xyz="0.03206 0.066416 -0.139225" rpy="0 0 0"/>
      <geometry>
        <mesh filename="package://Car_2_2023.10.04_description/meshes/Lidar_1.stl" scale="0.001 0.001 0.001"/>
      </geometry>
      <material name="silver"/>
    </visual>
    <collision>
      <origin xyz="0.03206 0.066416 -0.139225" rpy="0 0 0"/>
      <geometry>
        <mesh filename="package://Car_2_2023.10.04_description/meshes/Lidar_1.stl" scale="0.001 0.001 0.001"/>
      </geometry>
    </collision>
  </link>
  <joint name="Revolute 1" type="continuous">
    <origin xyz="-0.21406 -0.192916 0.023225" rpy="0 0 0"/>
    <parent link="base_link"/>
    <child link="Right_Back_Wheel_1"/>
    <axis xyz="-0.0 -1.0 -0.0"/>
  </joint>
  <joint name="Revolute 2" type="continuous">
    <origin xyz="-0.21406 0.060084 0.023225" rpy="0 0 0"/>
    <parent link="base_link"/>
    <child link="Left_Back_Wheel_1"/>
    <axis xyz="0.0 1.0 0.0"/>
  </joint>
  <joint name="Revolute 3" type="continuous">
    <origin xyz="-0.03206 -0.066416 0.139225" rpy="0 0 0"/>
    <parent link="base_link"/>
    <child link="Lidar_1"/>
    <axis xyz="0.0 0.0 1.0"/>
  </joint>
</robot>
