<?xml version="1.0" ?>
<!-- =================================================================================== -->
<!-- |    This document was autogenerated by xacro from urdf/car2.xacro                | -->
<!-- |    EDITING THIS FILE BY HAND IS NOT RECOMMENDED                                 | -->
<!-- =================================================================================== -->
<robot xmlns:xacro="http://www.ros.org/wiki/xacro" name="car2">
  <material name="silver">
    <color rgba="0.700 0.700 0.700 1.000"/>
  </material>
  <transmission name="Revolute 1_tran">
    <type>transmission_interface/SimpleTransmission</type>
    <joint name="Revolute 1">
      <hardwareInterface>hardware_interface/EffortJointInterface</hardwareInterface>
    </joint>
    <actuator name="Revolute 1_actr">
      <hardwareInterface>hardware_interface/EffortJointInterface</hardwareInterface>
      <mechanicalReduction>1</mechanicalReduction>
    </actuator>
  </transmission>
  <transmission name="Revolute 2_tran">
    <type>transmission_interface/SimpleTransmission</type>
    <joint name="Revolute 2">
      <hardwareInterface>hardware_interface/EffortJointInterface</hardwareInterface>
    </joint>
    <actuator name="Revolute 2_actr">
      <hardwareInterface>hardware_interface/EffortJointInterface</hardwareInterface>
      <mechanicalReduction>1</mechanicalReduction>
    </actuator>
  </transmission>
  <transmission name="Revolute 3_tran">
    <type>transmission_interface/SimpleTransmission</type>
    <joint name="Revolute 3">
      <hardwareInterface>hardware_interface/EffortJointInterface</hardwareInterface>
    </joint>
    <actuator name="Revolute 3_actr">
      <hardwareInterface>hardware_interface/EffortJointInterface</hardwareInterface>
      <mechanicalReduction>1</mechanicalReduction>
    </actuator>
  </transmission>
  <transmission name="Revolute 4_tran">
    <type>transmission_interface/SimpleTransmission</type>
    <joint name="Revolute 4">
      <hardwareInterface>hardware_interface/EffortJointInterface</hardwareInterface>
    </joint>
    <actuator name="Revolute 4_actr">
      <hardwareInterface>hardware_interface/EffortJointInterface</hardwareInterface>
      <mechanicalReduction>1</mechanicalReduction>
    </actuator>
  </transmission>
  <gazebo>
    <plugin name="control" filename="libgazebo_ros_control.so"/>
  </gazebo>
  <gazebo reference="base_link">
    <material>Gazebo/Silver</material>
    <mu1>0.2</mu1>
    <mu2>0.2</mu2>
    <selfCollide>true</selfCollide>
    <gravity>true</gravity>
  </gazebo>
  <gazebo reference="back_right_1">
    <material>Gazebo/Silver</material>
    <mu1>0.2</mu1>
    <mu2>0.2</mu2>
    <selfCollide>true</selfCollide>
  </gazebo>
  <gazebo reference="front_right_1">
    <material>Gazebo/Silver</material>
    <mu1>0.2</mu1>
    <mu2>0.2</mu2>
    <selfCollide>true</selfCollide>
  </gazebo>
  <gazebo reference="back_left_1">
    <material>Gazebo/Silver</material>
    <mu1>0.2</mu1>
    <mu2>0.2</mu2>
    <selfCollide>true</selfCollide>
  </gazebo>
  <gazebo reference="front_left_1">
    <material>Gazebo/Silver</material>
    <mu1>0.2</mu1>
    <mu2>0.2</mu2>
    <selfCollide>true</selfCollide>
  </gazebo>
  <link name="base_link">
    <inertial>
      <origin xyz="-1.5502442144694733e-05 0.0 0.025000000000000005" rpy="0 0 0"/>
      <mass value="15.89729201864544"/>
      <inertia ixx="0.058003" iyy="0.056761" izz="0.108213" ixy="0.0" iyz="0.0" ixz="0.0"/>
    </inertial>
    <visual>
      <origin xyz="0 0 0" rpy="0 0 0"/>
      <geometry>
        <mesh filename="package://car2_description/meshes/base_link.stl" scale="0.001 0.001 0.001"/>
      </geometry>
      <material name="silver"/>
    </visual>
    <collision>
      <origin xyz="0 0 0" rpy="0 0 0"/>
      <geometry>
        <mesh filename="package://car2_description/meshes/base_link.stl" scale="0.001 0.001 0.001"/>
      </geometry>
    </collision>
  </link>
  <link name="back_right_1">
    <inertial>
      <origin xyz="-2.9518161701047596e-07 -0.010000000000000009 -6.938893903907228e-18" rpy="0 0 0"/>
      <mass value="0.7891680745817556"/>
      <inertia ixx="0.000342" iyy="0.000631" izz="0.000342" ixy="0.0" iyz="0.0" ixz="-0.0"/>
    </inertial>
    <visual>
      <origin xyz="0.077498 0.12 -0.025" rpy="0 0 0"/>
      <geometry>
        <mesh filename="package://car2_description/meshes/back_right_1.stl" scale="0.001 0.001 0.001"/>
      </geometry>
      <material name="silver"/>
    </visual>
    <collision>
      <origin xyz="0.077498 0.12 -0.025" rpy="0 0 0"/>
      <geometry>
        <mesh filename="package://car2_description/meshes/back_right_1.stl" scale="0.001 0.001 0.001"/>
      </geometry>
    </collision>
  </link>
  <link name="front_right_1">
    <inertial>
      <origin xyz="0.0 -0.010000000000000009 -6.938893903907228e-18" rpy="0 0 0"/>
      <mass value="0.789168074581756"/>
      <inertia ixx="0.000342" iyy="0.000631" izz="0.000342" ixy="0.0" iyz="-0.0" ixz="-0.0"/>
    </inertial>
    <visual>
      <origin xyz="-0.075 0.12 -0.025" rpy="0 0 0"/>
      <geometry>
        <mesh filename="package://car2_description/meshes/front_right_1.stl" scale="0.001 0.001 0.001"/>
      </geometry>
      <material name="silver"/>
    </visual>
    <collision>
      <origin xyz="-0.075 0.12 -0.025" rpy="0 0 0"/>
      <geometry>
        <mesh filename="package://car2_description/meshes/front_right_1.stl" scale="0.001 0.001 0.001"/>
      </geometry>
    </collision>
  </link>
  <link name="back_left_1">
    <inertial>
      <origin xyz="-2.9518161701047596e-07 0.010000000000000009 -6.938893903907228e-18" rpy="0 0 0"/>
      <mass value="0.7891680745817556"/>
      <inertia ixx="0.000342" iyy="0.000631" izz="0.000342" ixy="-0.0" iyz="0.0" ixz="-0.0"/>
    </inertial>
    <visual>
      <origin xyz="0.077498 -0.12 -0.025" rpy="0 0 0"/>
      <geometry>
        <mesh filename="package://car2_description/meshes/back_left_1.stl" scale="0.001 0.001 0.001"/>
      </geometry>
      <material name="silver"/>
    </visual>
    <collision>
      <origin xyz="0.077498 -0.12 -0.025" rpy="0 0 0"/>
      <geometry>
        <mesh filename="package://car2_description/meshes/back_left_1.stl" scale="0.001 0.001 0.001"/>
      </geometry>
    </collision>
  </link>
  <link name="front_left_1">
    <inertial>
      <origin xyz="0.0 0.010000000000000009 -6.938893903907228e-18" rpy="0 0 0"/>
      <mass value="0.789168074581756"/>
      <inertia ixx="0.000342" iyy="0.000631" izz="0.000342" ixy="-0.0" iyz="0.0" ixz="-0.0"/>
    </inertial>
    <visual>
      <origin xyz="-0.075 -0.12 -0.025" rpy="0 0 0"/>
      <geometry>
        <mesh filename="package://car2_description/meshes/front_left_1.stl" scale="0.001 0.001 0.001"/>
      </geometry>
      <material name="silver"/>
    </visual>
    <collision>
      <origin xyz="-0.075 -0.12 -0.025" rpy="0 0 0"/>
      <geometry>
        <mesh filename="package://car2_description/meshes/front_left_1.stl" scale="0.001 0.001 0.001"/>
      </geometry>
    </collision>
  </link>
  <joint name="Revolute 1" type="continuous">
    <origin xyz="-0.077498 -0.12 0.025" rpy="0 0 0"/>
    <parent link="base_link"/>
    <child link="back_right_1"/>
    <axis xyz="0.0 -1.0 0.0"/>
  </joint>
  <joint name="Revolute 2" type="continuous">
    <origin xyz="0.075 -0.12 0.025" rpy="0 0 0"/>
    <parent link="base_link"/>
    <child link="front_right_1"/>
    <axis xyz="0.0 -1.0 0.0"/>
  </joint>
  <joint name="Revolute 3" type="continuous">
    <origin xyz="-0.077498 0.12 0.025" rpy="0 0 0"/>
    <parent link="base_link"/>
    <child link="back_left_1"/>
    <axis xyz="0.0 1.0 0.0"/>
  </joint>
  <joint name="Revolute 4" type="continuous">
    <origin xyz="0.075 0.12 0.025" rpy="0 0 0"/>
    <parent link="base_link"/>
    <child link="front_left_1"/>
    <axis xyz="0.0 1.0 0.0"/>
  </joint>
</robot>
